<mujoco model="franka">
    <compiler angle="radian" meshdir="meshes2/" />
    <option timestep="0.003" tolerance="1e-06" collision="predefined" cone="elliptic" jacobian="sparse" solver="CG" iterations="30" />
    <size njmax="500" nconmax="100" />
    <asset>
        <mesh name="link0_collision" file="link0_collision.STL" />
        <mesh name="link1_collision" file="link1_collision.STL" />
        <mesh name="link2_collision" file="link2_collision.STL" />
        <mesh name="link3_collision" file="link3_collision.STL" />
        <mesh name="link4_collision" file="link4_collision.STL" />
        <mesh name="link5_collision" file="link5_collision.STL" />
        <mesh name="link6_collision" file="link6_collision.STL" />
        <mesh name="link7_collision" file="link7_collision.STL" />
    </asset>
    <worldbody>
        <geom pos="0 0 0.01" type="mesh" rgba="1 1 1 1" mesh="link0_collision" />
        <body name="panda_link1" pos="0 0 0.343">
            <inertial pos="0 0 0.13" mass="2" diaginertia="0.0136667 0.0118667 0.003" />
            <joint name="panda_joint1" pos="0 0 0" axis="0 0 1" limited="true" range="-2.9671 2.9671" damping="5" frictionloss="1" />
            <geom type="mesh" rgba="1 1 1 1" mesh="link1_collision" />
            <body name="panda_link2" pos="0 0 0" quat="0.707107 -0.707107 0 0">
                <inertial pos="0 -0.06 0.07" mass="2" diaginertia="0.0136667 0.0118667 0.003" />
                <joint name="panda_joint2" pos="0 0 0" axis="0 0 1" limited="true" range="-1.8326 1.8326" damping="5" frictionloss="1" />
                <geom type="mesh" rgba="1 1 1 1" mesh="link2_collision" />
                <body name="panda_link3" pos="0 -0.316 0" quat="0.707107 0.707107 0 0">
                    <inertial pos="0 -0.06 0.13" mass="2" diaginertia="0.0136667 0.0118667 0.003" />
                    <joint name="panda_joint3" pos="0 0 0" axis="0 0 1" limited="true" range="-2.9671 2.9671" damping="5" frictionloss="1" />
                    <geom type="mesh" rgba="1 1 1 1" mesh="link3_collision" />
                    <body name="panda_link4" pos="0.0825 0 0" quat="0.707107 0.707107 0 0">
                        <inertial pos="0 0.06 0.07" mass="2" diaginertia="0.0136667 0.0118667 0.003" />
                        <joint name="panda_joint4" pos="0 0 0" axis="0 0 1" limited="true" range="-3.1416 0.0873" damping="5" frictionloss="1" />
                        <geom type="mesh" rgba="1 1 1 1" mesh="link4_collision" />
                        <body name="panda_link5" pos="-0.0825 0.384 0" quat="0.707107 -0.707107 0 0">
                            <inertial pos="0 0 0.124" mass="2" diaginertia="0.0126507 0.0108507 0.003" />
                            <joint name="panda_joint5" pos="0 0 0" axis="0 0 1" limited="true" range="-2.9671 2.9671" damping="5" frictionloss="1" />
                            <geom type="mesh" rgba="1 1 1 1" mesh="link5_collision" />
                            <body name="panda_link6" pos="0 0 0" quat="0.707107 0.707107 0 0">
                                <inertial pos="0 0 0" mass="1" diaginertia="0.00260417 0.00260417 0.00260417" />
                                <joint name="panda_joint6" pos="0 0 0" axis="0 0 1" limited="true" range="-0.0873 3.8223" damping="5" frictionloss="1" />
                                <geom type="mesh" rgba="1 1 1 1" mesh="link6_collision" />
                                <body name="panda_link7" pos="0.088 0 0" quat="0.707107 0.707107 0 0">
                                    <inertial pos="0 0 0" quat="0.5 0.5 -0.5 0.5" mass="0.2" diaginertia="0.00012 6.66667e-05 6.66667e-05" />
                                    <joint name="panda_joint7" pos="0 0 0" axis="0 0 1" limited="true" range="-2.9671 2.9671" damping="5" frictionloss="1" />
                                    <geom type="mesh" rgba="1 1 1 1" mesh="link7_collision" />
                                </body>
                            </body>
                        </body>
                    </body>
                </body>
            </body>
        </body>
    </worldbody>
</mujoco>
